Workbook

Sheet AREAS
A1: ID | B1: Nome | C1: Links | D1: [ON / OFF] | E1: Status da área | F1: # UAU LAND-BANK | G1: # Workflow | H1: Empresa UAU | I1: Obra UAU | J1: Código Modelo | K1: Regional | L1: Cidade | M1: UF | N1: Empreendimento | O1: Tipo de Contrato | P1: Valor de Compra da Área - Aquisição (R$mm) | Q1: Tipo | R1: Projeto Feito | S1: Year | T1: Data de Lançamento | U1: Participação Buriti | V1: Participação Terreneiro (não paga obra) | W1: Participação Buriti + Terreneiro | X1: Comisão / Terreneiro | Y1: Adm. E Manutenção / Terreneiro | Z1: Tributos / Terreneiro | AA1: Participação Líquida Terreneiro | AB1: Participação de Sócios Minoritários (paga obra) | AC1: Area Total m2 | AD1: Data de Inicio de Construção | AE1: Custo Total do Terreno (Pré Rateio - R$mm) | AF1: Custo Total do Terreno (% do VGV) | AG1: Custo de Construção (Pré Rateio - R$mm) | AH1: Valor m2 Obra | AI1: m2 por Unidade | AJ1: Total de Unidades | AK1: Valor m2 Venda | AL1: VGV Total (R$mm) | AM1: VGV Total (R$mm) BT | AN1: Valor médio por terreno | AO1: Custo médio por terreno | AP1: % Paga obra | AQ1: Margem
A2: MAP001 | B2: CIDADE JARDIM - ETP I - BELA VISTA | C2: https://earth.google.com/web/search/BELA+VISTA/@-16.96124568,-48.94579579,823.03102905a,3707.10942264d,35y,-0h,0t,0r/data=CnkaSxJFCiUweDkzNWYyNTZjZmU4NDk4OGQ6MHhiNDk0MzE3NTE3MDU3YTA5GVl5E43_-DDAIcOVWL7TeUjAKgpCRUxBIFZJU1RBGAIgASImCiQJ0WMLs4K1IMAREBK2sOjBIMAZM_Z2zLqhSMAh4pu9YBioSMBCAggBOgMKATBCAggASggIl-fxrwUQAA?authuser=0 | D2: 1 | E2: LandBank | G2: 2040 | J2: 355 | K2: CENTRO-OESTE I | L2: BELA VISTA DE GOIÁS | M2: GO | N2: CIDADE JARDIM - ETP I | O2: Arrematação judicial | P2: 11775750 | Q2: Loteamento | R2: Sim | S2: 2026 | T2: 46203 | U2: 0.75 | V2: 0.25 | W2: =SUM(U2:V2) -> 1 | X2: 0.05 | Y2: 0.09 | Z2: 0.068 | AA2: 0.198 | AC2: =AI2*AJ2 -> 222798.36 | AE2: =P2/10^6 -> 11.77575 | AF2: =IF(AL2=0,0,AE2/AL2) -> 0.10786499 | AG2: =(AH2*AI2*AJ2)/10^6 -> 32.974158 | AH2: 148 | AI2: 305.20324 | AJ2: 730 | AK2: 490 | AL2: =(AK2*AJ2*AI2)/10^6 -> 109.1712 | AM2: =AL2*U2 -> 81.878399 | AN2: 149549.59 | AO2: =AH2*AI2 -> 45170.079 | AP2: =U2+AB2 -> 0.75 | AQ2: =AL2*AP2/(AG2+AE2) -> 1.8296887
A3: MAP001 | B3: CIDADE JARDIM - ETP II - BELA VISTA | C3: https://earth.google.com/web/search/BELA+VISTA/@-16.96124568,-48.94579579,823.03102905a,3707.10942264d,35y,-0h,0t,0r/data=CnkaSxJFCiUweDkzNWYyNTZjZmU4NDk4OGQ6MHhiNDk0MzE3NTE3MDU3YTA5GVl5E43_-DDAIcOVWL7TeUjAKgpCRUxBIFZJU1RBGAIgASImCiQJ0WMLs4K1IMAREBK2sOjBIMAZM_Z2zLqhSMAh4pu9YBioSMBCAggBOgMKATBCAggASggIl-fxrwUQAA?authuser=0 | D3: 1 | E3: LandBank | G3: 2040 | J3: 356 | K3: CENTRO-OESTE I | L3: BELA VISTA DE GOIÁS | M3: GO | N3: CIDADE JARDIM - ETP II | O3: Arrematação judicial | P3: 11775750 | Q3: Loteamento | R3: Sim | S3: 2028 | T3: 46934 | U3: 0.75 | V3: 0.25 | W3: =SUM(U3:V3) -> 1 | X3: 0.05 | Y3: 0.09 | Z3: 0.068 | AA3: 0.198 | AC3: =AI3*AJ3 -> 222798.36 | AE3: =P3/10^6 -> 11.77575 | AF3: =IF(AL3=0,0,AE3/AL3) -> 0.10786499 | AG3: =(AH3*AI3*AJ3)/10^6 -> 32.974158 | AH3: 148 | AI3: 304.78573 | AJ3: 731 | AK3: 490 | AL3: =(AK3*AJ3*AI3)/10^6 -> 109.1712 | AM3: =AL3*U3 -> 81.878399 | AN3: 149345.01 | AO3: =AH3*AI3 -> 45108.287 | AP3: =U3+AB3 -> 0.75 | AQ3: =AL3*AP3/(AG3+AE3) -> 1.8296887
A4: MAP122 | B4: JARDIM DO CERRADO 5 - GOIÂNIA | C4: https://earth.google.com/web/search/GOI%c3%82NIA/@-16.67746594,-49.42770992,858.01737984a,4789.30417081d,35y,9.31126662h,0.18897674t,360r/data=CiwiJgokCTImrsNH8yrAEajobj-t-irAGWOHbhWxkEjAIXn8jCOOlEjAQgIIAToDCgEwQgIIAEoICJfn8a8FEAA?authuser=0 | D4: 1 | E4: LandBank | G4: 2770 | J4: 358 | K4: CENTRO-OESTE II | L4: GOIÂNIA | M4: GO | N4: JARDIM DO CERRADO 5 | O4: Parceria | P4: 0 | Q4: Loteamento | R4: - | S4: 2030 | T4: 47848 | U4: 0.8 | W4: =SUM(U4:V4) -> 0.8 | AA4: 0.198 | AB4: 0.2 | AC4: =AI4*AJ4 -> 260020.4 | AE4: =P4/10^6 -> 0 | AF4: =IF(AL4=0,0,AE4/AL4) -> 0 | AG4: =(AH4*AI4*AJ4)/10^6 -> 38.483019 | AH4: 148 | AI4: 296.82694 | AJ4: 876 | AK4: 500 | AL4: =(AK4*AJ4*AI4)/10^6 -> 130.0102 | AM4: =AL4*U4 -> 104.00816 | AN4: 148413.47 | AO4: =AH4*AI4 -> 43930.387 | AP4: =U4+AB4 -> 1 | AQ4: =AL4*AP4/(AG4+AE4) -> 3.3783784
A5: MAP122 | B5: JARDIM DO CERRADO 6 - GOIÂNIA | C5: https://earth.google.com/web/search/GOI%c3%82NIA/@-16.67746594,-49.42770992,858.01737984a,4789.30417081d,35y,9.31126662h,0.18897674t,360r/data=CiwiJgokCTImrsNH8yrAEajobj-t-irAGWOHbhWxkEjAIXn8jCOOlEjAQgIIAToDCgEwQgIIAEoICJfn8a8FEAA?authuser=0 | D5: 1 | E5: LandBank | G5: 2770 | J5: 359 | K5: CENTRO-OESTE II | L5: GOIÂNIA | M5: GO | N5: JARDIM DO CERRADO 6 | O5: Parceria | P5: 0 | Q5: Loteamento | R5: - | S5: 2029 | T5: 47483 | U5: 0.8 | W5: =SUM(U5:V5) -> 0.8 | AA5: 0.198 | AB5: 0.2 | AC5: =AI5*AJ5 -> 134090.93 | AE5: =P5/10^6 -> 0 | AF5: =IF(AL5=0,0,AE5/AL5) -> 0 | AG5: =(AH5*AI5*AJ5)/10^6 -> 19.845458 | AH5: 148 | AI5: 292.1371 | AJ5: 459 | AK5: 500 | AL5: =(AK5*AJ5*AI5)/10^6 -> 67.045465 | AM5: =AL5*U5 -> 53.636372 | AN5: 146068.55 | AO5: =AH5*AI5 -> 43236.291 | AP5: =U5+AB5 -> 1 | AQ5: =AL5*AP5/(AG5+AE5) -> 3.3783784
A6: MAP122 | B6: JARDIM DO CERRADO 7 - GOIÂNIA | C6: https://earth.google.com/web/search/GOI%c3%82NIA/@-16.67746594,-49.42770992,858.01737984a,4789.30417081d,35y,9.31126662h,0.18897674t,360r/data=CiwiJgokCTImrsNH8yrAEajobj-t-irAGWOHbhWxkEjAIXn8jCOOlEjAQgIIAToDCgEwQgIIAEoICJfn8a8FEAA?authuser=0 | D6: 1 | E6: LandBank | G6: 2770 | J6: 360 | K6: CENTRO-OESTE II | L6: GOIÂNIA | M6: GO | N6: JARDIM DO CERRADO 7 | O6: Parceria | P6: 0 | Q6: Loteamento | R6: - | S6: 2026 | T6: 46295 | U6: 0.8 | W6: =SUM(U6:V6) -> 0.8 | AA6: 0.198 | AB6: 0.2 | AC6: =AI6*AJ6 -> 72284.41 | AE6: =P6/10^6 -> 0 | AF6: =IF(AL6=0,0,AE6/AL6) -> 0 | AG6: =(AH6*AI6*AJ6)/10^6 -> 10.698093 | AH6: 148 | AI6: 384.49154 | AJ6: 188 | AK6: 500 | AL6: =(AK6*AJ6*AI6)/10^6 -> 36.142205 | AM6: =AL6*U6 -> 28.913764 | AN6: 192245.77 | AO6: =AH6*AI6 -> 56904.748 | AP6: =U6+AB6 -> 1 | AQ6: =AL6*AP6/(AG6+AE6) -> 3.3783784
A7: MAP122 | B7: JARDIM DO CERRADO 8 - GOIÂNIA | C7: https://earth.google.com/web/search/GOI%c3%82NIA/@-16.67746594,-49.42770992,858.01737984a,4789.30417081d,35y,9.31126662h,0.18897674t,360r/data=CiwiJgokCTImrsNH8yrAEajobj-t-irAGWOHbhWxkEjAIXn8jCOOlEjAQgIIAToDCgEwQgIIAEoICJfn8a8FEAA?authuser=0 | D7: 1 | E7: LandBank | G7: 2770 | J7: 361 | K7: CENTRO-OESTE II | L7: GOIÂNIA | M7: GO | N7: JARDIM DO CERRADO 8 | O7: Parceria | P7: 0 | Q7: Loteamento | R7: - | S7: 2026 | T7: 46295 | U7: 0.8 | W7: =SUM(U7:V7) -> 0.8 | AA7: 0.198 | AB7: 0.2 | AC7: =AI7*AJ7 -> 78369.024 | AE7: =P7/10^6 -> 0 | AF7: =IF(AL7=0,0,AE7/AL7) -> 0 | AG7: =(AH7*AI7*AJ7)/10^6 -> 11.598615 | AH7: 148 | AI7: 279.88937 | AJ7: 280 | AK7: 500 | AL7: =(AK7*AJ7*AI7)/10^6 -> 39.184512 | AM7: =AL7*U7 -> 31.347609 | AN7: 139944.68 | AO7: =AH7*AI7 -> 41423.627 | AP7: =U7+AB7 -> 1 | AQ7: =AL7*AP7/(AG7+AE7) -> 3.3783784
A8: MAP122 | B8: JARDIM DO CERRADO 8 II - GOIÂNIA | C8: https://earth.google.com/web/search/GOI%c3%82NIA/@-16.67746594,-49.42770992,858.01737984a,4789.30417081d,35y,9.31126662h,0.18897674t,360r/data=CiwiJgokCTImrsNH8yrAEajobj-t-irAGWOHbhWxkEjAIXn8jCOOlEjAQgIIAToDCgEwQgIIAEoICJfn8a8FEAA?authuser=0 | D8: 1 | E8: LandBank | G8: 2770 | J8: 362 | K8: CENTRO-OESTE II | L8: GOIÂNIA | M8: GO | N8: JARDIM DO CERRADO 8 II | O8: Parceria | P8: 0 | Q8: Loteamento | R8: - | S8: 2028 | T8: 47118 | U8: 0.8 | W8: =SUM(U8:V8) -> 0.8 | AA8: 0.198 | AB8: 0.2 | AC8: =AI8*AJ8 -> 183607.43 | AE8: =P8/10^6 -> 0 | AF8: =IF(AL8=0,0,AE8/AL8) -> 0 | AG8: =(AH8*AI8*AJ8)/10^6 -> 27.173899 | AH8: 148 | AI8: 279.88937 | AJ8: 656 | AK8: 500 | AL8: =(AK8*AJ8*AI8)/10^6 -> 91.803713 | AM8: =AL8*U8 -> 73.442971 | AN8: 139944.68 | AO8: =AH8*AI8 -> 41423.627 | AP8: =U8+AB8 -> 1 | AQ8: =AL8*AP8/(AG8+AE8) -> 3.3783784
A9: MAP122 | B9: JARDIM DO CERRADO 9 - GOIÂNIA | C9: https://earth.google.com/web/search/GOI%c3%82NIA/@-16.67746594,-49.42770992,858.01737984a,4789.30417081d,35y,9.31126662h,0.18897674t,360r/data=CiwiJgokCTImrsNH8yrAEajobj-t-irAGWOHbhWxkEjAIXn8jCOOlEjAQgIIAToDCgEwQgIIAEoICJfn8a8FEAA?authuser=0 | D9: 1 | E9: LandBank | G9: 2770 | J9: 363 | K9: CENTRO-OESTE II | L9: GOIÂNIA | M9: GO | N9: JARDIM DO CERRADO 9 | O9: Parceria | P9: 0 | Q9: Loteamento | R9: - | S9: 2026 | T9: 46387 | U9: 0.8 | W9: =SUM(U9:V9) -> 0.8 | AA9: 0.198 | AB9: 0.2 | AC9: =AI9*AJ9 -> 132666.99 | AE9: =P9/10^6 -> 0 | AF9: =IF(AL9=0,0,AE9/AL9) -> 0 | AG9: =(AH9*AI9*AJ9)/10^6 -> 19.634715 | AH9: 148 | AI9: 282.87205 | AJ9: 469 | AK9: 500 | AL9: =(AK9*AJ9*AI9)/10^6 -> 66.333495 | AM9: =AL9*U9 -> 53.066796 | AN9: 141436.02 | AO9: =AH9*AI9 -> 41865.063 | AP9: =U9+AB9 -> 1 | AQ9: =AL9*AP9/(AG9+AE9) -> 3.3783784
A10: MAP122 | B10: JARDIM DO CERRADO 10 - GOIÂNIA | C10: https://earth.google.com/web/search/GOI%c3%82NIA/@-16.67746594,-49.42770992,858.01737984a,4789.30417081d,35y,9.31126662h,0.18897674t,360r/data=CiwiJgokCTImrsNH8yrAEajobj-t-irAGWOHbhWxkEjAIXn8jCOOlEjAQgIIAToDCgEwQgIIAEoICJfn8a8FEAA?authuser=0 | D10: 1 | E10: LandBank | G10: 2770 | J10: 364 | K10: CENTRO-OESTE II | L10: GOIÂNIA | M10: GO | N10: JARDIM DO CERRADO 10 | O10: Parceria | P10: 0 | Q10: Loteamento | R10: - | S10: 2027 | T10: 46752 | U10: 0.8 | W10: =SUM(U10:V10) -> 0.8 | AA10: 0.198 | AB10: 0.2 | AC10: =AI10*AJ10 -> 177762.71 | AE10: =P10/10^6 -> 0 | AF10: =IF(AL10=0,0,AE10/AL10) -> 0 | AG10: =(AH10*AI10*AJ10)/10^6 -> 26.308881 | AH10: 148 | AI10: 428.34388 | AJ10: 415 | AK10: 500 | AL10: =(AK10*AJ10*AI10)/10^6 -> 88.881355 | AM10: =AL10*U10 -> 71.105084 | AN10: 214171.94 | AO10: =AH10*AI10 -> 63394.894 | AP10: =U10+AB10 -> 1 | AQ10: =AL10*AP10/(AG10+AE10) -> 3.3783784
A11: MAP122 | B11: JARDIM DO CERRADO 11 - GOIÂNIA | C11: https://earth.google.com/web/search/GOI%c3%82NIA/@-16.67746594,-49.42770992,858.01737984a,4789.30417081d,35y,9.31126662h,0.18897674t,360r/data=CiwiJgokCTImrsNH8yrAEajobj-t-irAGWOHbhWxkEjAIXn8jCOOlEjAQgIIAToDCgEwQgIIAEoICJfn8a8FEAA?authuser=0 | D11: 1 | E11: LandBank | G11: 2770 | J11: 365 | K11: CENTRO-OESTE II | L11: GOIÂNIA | M11: GO | N11: JARDIM DO CERRADO 11 | O11: Parceria | P11: 0 | Q11: Loteamento | R11: - | S11: 2029 | T11: 47483 | U11: 0.8 | W11: =SUM(U11:V11) -> 0.8 | AA11: 0.198 | AB11: 0.2 | AC11: =AI11*AJ11 -> 51071.98 | AE11: =P11/10^6 -> 0 | AF11: =IF(AL11=0,0,AE11/AL11) -> 0 | AG11: =(AH11*AI11*AJ11)/10^6 -> 7.558653 | AH11: 148 | AI11: 263.25763 | AJ11: 194 | AK11: 500 | AL11: =(AK11*AJ11*AI11)/10^6 -> 25.53599 | AM11: =AL11*U11 -> 20.428792 | AN11: 131628.81 | AO11: =AH11*AI11 -> 38962.129 | AP11: =U11+AB11 -> 1 | AQ11: =AL11*AP11/(AG11+AE11) -> 3.3783784
A12: MAP125 | B12: RESIDENCIAL PAINEIRAS | D12: 1 | E12: LandBank | G12: 2177 | K12: CENTRO-OESTE II | L12: PORTO VELHO | M12: RO | N12: RESIDENCIAL PAINEIRAS | O12: Parceria | P12: 0 | Q12: Loteamento | R12: Sim | U12: 0.8 | W12: =SUM(U12:V12) -> 0.8 | AA12: 0.198 | AB12: 0.2 | AC12: =AI12*AJ12 -> 363235.45 | AE12: =P12/10^6 -> 0 | AF12: =IF(AL12=0,0,AE12/AL12) -> 0 | AG12: =(AH12*AI12*AJ12)/10^6 -> 48.346638 | AH12: 133.1 | AI12: 215.57 | AJ12: 1685 | AK12: 380 | AL12: =(AK12*AJ12*AI12)/10^6 -> 138.02947 | AM12: =AL12*U12 -> 110.42358 | AN12: 114000 | AO12: =AH12*AI12 -> 28692.367 | AP12: =U12+AB12 -> 1 | AQ12: =AL12*AP12/(AG12+AE12) -> 2.8549962
A13: MAP133 | B13: ANAMARIA SANTOS GUIMARÃES | D13: 1 | E13: LandBank | G13: 2041 | K13: CENTRO-OESTE II | L13: CALDAS NOVAS | M13: GO | N13: A DEFINIR | O13: Parceria | P13: 0 | Q13: Loteamento | U13: 0.725 | V13: =27.5%-15% -> 0.125 | W13: =SUM(U13:V13) -> 0.85 | AA13: 0.198 | AB13: 0.15 | AC13: 1669.242 | AE13: =P13/10^6 -> 0 | AF13: =IF(AL13=0,0,AE13/AL13) -> 0 | AG13: =(AH13*AI13*AJ13)/10^6 -> 196.54908 | AH13: 240 | AI13: 219.5 | AJ13: 3731 | AK13: 520 | AL13: =(AK13*AJ13*AI13)/10^6 -> 425.85634 | AM13: =AL13*U13 -> 308.74585 | AN13: 114140 | AO13: =AH13*AI13 -> 52680 | AP13: =U13+AB13 -> 0.875 | AQ13: =AL13*AP13/(AG13+AE13) -> 1.8958333
A14: MAP032 | B14: RESIDENCIAL ALTO DAS BARAUNAS II - ARAPIRACA | C14: https://earth.google.com/web/search/ARAPIRACA/@-9.74896182,-36.69647245,245.55478327a,4738.09539736d,35y,0h,0t,0r/data=CiwiJgokCclCL3e0IS_AESFNk5j5MS_AGZRIeMyvpUfAIcPoSk9ErkfAQgIIAToDCgEwQgIIAEoICJfn8a8FEAA?authuser=0 | D14: 1 | E14: LandBank | G14: 2045 | J14: 194 | K14: NORDESTE I | L14: ARAPIRACA | M14: AL | N14: RESIDENCIAL ALTO DAS BARAUNAS II | O14: Parceria | P14: 0 | Q14: Loteamento | R14: - | S14: 2027 | T14: 46568 | U14: 0.5304 | V14: 0.337 | W14: =SUM(U14:V14) -> 0.8674 | X14: 0.05 | Y14: 0.09 | Z14: 0.068 | AA14: 0.198 | AB14: 0.1326 | AC14: =AI14*AJ14 -> 169253.49 | AE14: =P14/10^6 -> 0 | AF14: =IF(AL14=0,0,AE14/AL14) -> 0 | AG14: =(AH14*AI14*AJ14)/10^6 -> 20.310419 | AH14: 120 | AI14: 187.64245 | AJ14: 902 | AK14: 426.10642 | AL14: =(AK14*AJ14*AI14)/10^6 -> 72.12 | AM14: =AL14*U14 -> 38.252448 | AN14: 79955.654 | AO14: =AH14*AI14 -> 22517.094 | AP14: =U14+AB14 -> 0.663 | AQ14: =AL14*AP14/(AG14+AE14) -> 2.354238
A15: MAP032 | B15: RESIDENCIAL ALTO DAS BARAUNAS II - SPT2 - ARAPIRACA | C15: https://earth.google.com/web/search/ARAPIRACA/@-9.74896182,-36.69647245,245.55478327a,4738.09539736d,35y,0h,0t,0r/data=CiwiJgokCclCL3e0IS_AESFNk5j5MS_AGZRIeMyvpUfAIcPoSk9ErkfAQgIIAToDCgEwQgIIAEoICJfn8a8FEAA?authuser=0 | D15: 1 | E15: LandBank | G15: 2045 | J15: 195 | K15: NORDESTE I | L15: ARAPIRACA | M15: AL | N15: RESIDENCIAL ALTO DAS BARAUNAS II - SPT2 | O15: Parceria | P15: 0 | Q15: Loteamento | R15: - | S15: 2028 | T15: 46934 | U15: 0.5304 | V15: 0.337 | W15: =SUM(U15:V15) -> 0.8674 | X15: 0.05 | Y15: 0.09 | Z15: 0.068 | AA15: 0.198 | AB15: 0.1326 | AC15: =AI15*AJ15 -> 169253.49 | AE15: =P15/10^6 -> 0 | AF15: =IF(AL15=0,0,AE15/AL15) -> 0 | AG15: =(AH15*AI15*AJ15)/10^6 -> 20.310419 | AH15: 120 | AI15: 187.85071 | AJ15: 901 | AK15: 426.10642 | AL15: =(AK15*AJ15*AI15)/10^6 -> 72.12 | AM15: =AL15*U15 -> 38.252448 | AN15: 80044.395 | AO15: =AH15*AI15 -> 22542.086 | AP15: =U15+AB15 -> 0.663 | AQ15: =AL15*AP15/(AG15+AE15) -> 2.354238
A16: MAP033 | B16: BURITI GARDEN PRIME - MARECHAL DEODORO | C16: https://earth.google.com/web/search/MARECHAL+DEODORO/@-9.75268373,-35.84765408,4.2701174a,3214.95034437d,35y,0h,0t,0r/data=CiwiJgokCWeqOyo7eCPAETh3cFu0hiPAGVxp7S1rVULAIVnrvdbgXELAQgIIAToDCgEwQgIIAEoICJfn8a8FEAA?authuser=0 | D16: 1 | E16: LandBank | G16: 2047 | J16: 196 | K16: NORDESTE I | L16: MARECHAL DEODORO | M16: AL | N16: BURITI GARDEN PRIME | O16: Parceria | P16: 0 | Q16: Condominio | R16: Sim | S16: 2026 | T16: 46203 | U16: 0.5086 | V16: 0.3642 | W16: =SUM(U16:V16) -> 0.8728 | X16: 0.05 | Y16: 0.09 | Z16: 0.068 | AA16: 0.198 | AB16: 0.1272 | AC16: =AI16*AJ16 -> 164975.96 | AE16: =P16/10^6 -> 0 | AF16: =IF(AL16=0,0,AE16/AL16) -> 0 | AG16: =(AH16*AI16*AJ16)/10^6 -> 42.89375 | AH16: 260 | AI16: 246.97 | AJ16: 668 | AK16: 949.68418 | AL16: =(AK16*AJ16*AI16)/10^6 -> 156.67506 | AM16: =AL16*U16 -> 79.684935 | AN16: 260000 | AO16: =AH16*AI16 -> 64212.2 | AP16: =U16+AB16 -> 0.6358 | AQ16: =AL16*AP16/(AG16+AE16) -> 2.3223431
A17: MAP034 | B17: RESIDENCIAL CIDADE JARDIM III - RIO LARGO | C17: https://earth.google.com/web/search/RIO+LARGO/@-9.52900304,-35.81653115,112.35298923a,4987.59724811d,35y,0.00000121h,0t,0r/data=CiwiJgokCbfopBmzfCPAEeMgyVIMhiPAGTrKKDMX6kHAIcF9G6ro7kHAQgIIAToDCgEwQgIIAEoICJfn8a8FEAA?authuser=0 | D17: 1 | E17: LandBank | G17: 2049 | J17: 197 | K17: NORDESTE I | L17: RIO LARGO | M17: AL | N17: RESIDENCIAL CIDADE JARDIM III | O17: Compra e Venda | P17: 1923793.1 | Q17: Loteamento | R17: Sim | S17: 2026 | T17: 46203 | U17: 0.8 | W17: =SUM(U17:V17) -> 0.8 | AA17: 0.198 | AB17: 0.2 | AC17: =AI17*AJ17 -> 247500 | AE17: =P17/10^6 -> 1.9237931 | AF17: =IF(AL17=0,0,AE17/AL17) -> 0.016446441 | AG17: =(AH17*AI17*AJ17)/10^6 -> 29.7 | AH17: 120 | AI17: 165 | AJ17: 1500 | AK17: 472.61904 | AL17: =(AK17*AJ17*AI17)/10^6 -> 116.97321 | AM17: =AL17*U17 -> 93.57857 | AN17: 79872.618 | AO17: =AH17*AI17 -> 19800 | AP17: =U17+AB17 -> 1 | AQ17: =AL17*AP17/(AG17+AE17) -> 3.6988989
A18: MAP034 | B18: RESIDENCIAL CIDADE JARDIM III - STP 2 - RIO LARGO | C18: https://earth.google.com/web/search/RIO+LARGO/@-9.52900304,-35.81653115,112.35298923a,4987.59724811d,35y,0.00000121h,0t,0r/data=CiwiJgokCbfopBmzfCPAEeMgyVIMhiPAGTrKKDMX6kHAIcF9G6ro7kHAQgIIAToDCgEwQgIIAEoICJfn8a8FEAA?authuser=0 | D18: 1 | E18: LandBank | G18: 2049 | J18: 198 | K18: NORDESTE I | L18: RIO LARGO | M18: AL | N18: RESIDENCIAL CIDADE JARDIM III - STP 2 | O18: Compra e Venda | P18: 1923792 | Q18: Loteamento | R18: Sim | S18: 2027 | T18: 46477 | U18: 0.8 | W18: =SUM(U18:V18) -> 0.8 | AA18: 0.198 | AB18: 0.2 | AC18: =AI18*AJ18 -> 165000 | AE18: =P18/10^6 -> 1.923792 | AF18: =IF(AL18=0,0,AE18/AL18) -> 0.024669648 | AG18: =(AH18*AI18*AJ18)/10^6 -> 19.8 | AH18: 120 | AI18: 165 | AJ18: 1000 | AK18: 472.61904 | AL18: =(AK18*AJ18*AI18)/10^6 -> 77.982142 | AM18: =AL18*U18 -> 62.385714 | AN18: 79872.618 | AO18: =AH18*AI18 -> 19800 | AP18: =U18+AB18 -> 1 | AQ18: =AL18*AP18/(AG18+AE18) -> 3.5897113
A19: MAP034 | B19: RESIDENCIAL CIDADE JARDIM III - STP 3 - RIO LARGO | C19: https://earth.google.com/web/search/RIO+LARGO/@-9.52900304,-35.81653115,112.35298923a,4987.59724811d,35y,0.00000121h,0t,0r/data=CiwiJgokCbfopBmzfCPAEeMgyVIMhiPAGTrKKDMX6kHAIcF9G6ro7kHAQgIIAToDCgEwQgIIAEoICJfn8a8FEAA?authuser=0 | D19: 1 | E19: LandBank | G19: 2049 | J19: 199 | K19: NORDESTE I | L19: RIO LARGO | M19: AL | N19: RESIDENCIAL CIDADE JARDIM III - STP 3 | O19: Compra e Venda | P19: 1923792 | Q19: Loteamento | R19: Sim | S19: 2028 | T19: 46934 | U19: 0.8 | W19: =SUM(U19:V19) -> 0.8 | AA19: 0.198 | AB19: 0.2 | AC19: =AI19*AJ19 -> 114840 | AE19: =P19/10^6 -> 1.923792 | AF19: =IF(AL19=0,0,AE19/AL19) -> 0.035444897 | AG19: =(AH19*AI19*AJ19)/10^6 -> 13.7808 | AH19: 120 | AI19: 165 | AJ19: 696 | AK19: 472.61904 | AL19: =(AK19*AJ19*AI19)/10^6 -> 54.275571 | AM19: =AL19*U19 -> 43.420457 | AN19: 79872.618 | AO19: =AH19*AI19 -> 19800 | AP19: =U19+AB19 -> 1 | AQ19: =AL19*AP19/(AG19+AE19) -> 3.4560319
A20: MAP035 | B20: RESIDENCIAL JARDIM AMERICA II - PENEDO | C20: https://earth.google.com/web/search/Penedo,+AL/@-10.25735808,-36.57115779,78.36658822a,3198.69005319d,35y,0h,0t,0r/data=CiwiJgokCSEY7vitZSLAEUE54MEYuCPAGb-vF-6sm0HAIR2ubXgmSkLAQgIIAToDCgEwQgIIAEoICJfn8a8FEAA?authuser=0 | D20: 1 | E20: LandBank | G20: 2048 | J20: 200 | K20: NORDESTE I | L20: PENEDO | M20: AL | N20: RESIDENCIAL JARDIM AMERICA II | O20: Compra e Venda | P20: 4000000 | Q20: Loteamento | R20: Sim | S20: 2026 | T20: 46203 | U20: 0.8 | W20: =SUM(U20:V20) -> 0.8 | AA20: 0.198 | AB20: 0.2 | AC20: =AI20*AJ20 -> 117415.64 | AE20: =P20/10^6 -> 4 | AF20: =IF(AL20=0,0,AE20/AL20) -> 0.079225609 | AG20: =(AH20*AI20*AJ20)/10^6 -> 14.089877 | AH20: 120 | AI20: 207.81529 | AJ20: 565 | AK20: 430 | AL20: =(AK20*AJ20*AI20)/10^6 -> 50.488725 | AM20: =AL20*U20 -> 40.39098 | AN20: 89360.576 | AO20: =AH20*AI20 -> 24937.835 | AP20: =U20+AB20 -> 1 | AQ20: =AL20*AP20/(AG20+AE20) -> 2.7909933
A21: MAP036 | B21: RESIDENCIAL JARDIM EUROPA 2 - ALAGOINHA | C21: https://earth.google.com/web/search/RESIDENCIAL+JARDIM+EUROPA+2+-+ALAGOINHA/@-12.16901753,-38.4079717,117.33325024a,3592.41516492d,35y,0h,0t,0r/data=CiwiJgokCVvsaFFQZxrAESI5vVrxVB7AGWgJCTaDWkHAIWhUtp4sXELAQgIIAToDCgEwQgIIAEoICJfn8a8FEAA?authuser=0 | D21: 1 | E21: LandBank | G21: 2044 | J21: 201 | K21: NORDESTE I | L21: ALAGOINHA | M21: PB | N21: RESIDENCIAL JARDIM EUROPA 2 | O21: Compra e Venda | P21: 2000000 | Q21: Loteamento | R21: Sim | S21: 2028 | T21: 46843 | U21: 0.8 | W21: =SUM(U21:V21) -> 0.8 | AA21: 0.198 | AB21: 0.2 | AC21: =AI21*AJ21 -> 187500 | AE21: =P21/10^6 -> 2 | AF21: =IF(AL21=0,0,AE21/AL21) -> 0.023188406 | AG21: =(AH21*AI21*AJ21)/10^6 -> 22.5 | AH21: 120 | AI21: 180 | AJ21: 1041.6667 | AK21: 460 | AL21: =(AK21*AJ21*AI21)/10^6 -> 86.25 | AM21: =AL21*U21 -> 69 | AN21: 82800 | AO21: =AH21*AI21 -> 21600 | AP21: =U21+AB21 -> 1 | AQ21: =AL21*AP21/(AG21+AE21) -> 3.5204082
A22: MAP037 | B22: RESIDENCIAL JARDIM EUROPA - BARRA DOS COQUEIROS | C22: https://earth.google.com/web/search/BARRA+DOS+COQUEIROS/@-10.86709266,-36.98473154,9.11625276a,6838.59037115d,35y,0h,0t,0r/data=CiwiJgokCez0LUwI4RzAEc6AbPlB_xzAGXUWKXAsqkPAIYL6q2XpsUPAQgIIAToDCgEwQgIIAEoICJfn8a8FEAA?authuser=0 | D22: 1 | E22: LandBank | G22: 2046 | J22: 202 | K22: NORDESTE I | L22: BARRA DOS COQUEIROS | M22: SE | N22: RESIDENCIAL JARDIM EUROPA | O22: Compra e Venda | P22: 4000000 | Q22: Loteamento | R22: - | S22: 2027 | T22: 46568 | U22: 0.8 | W22: =SUM(U22:V22) -> 0.8 | AA22: 0.198 | AB22: 0.2 | AC22: =AI22*AJ22 -> 204159.05 | AE22: =P22/10^6 -> 4 | AF22: =IF(AL22=0,0,AE22/AL22) -> 0.045564111 | AG22: =(AH22*AI22*AJ22)/10^6 -> 24.499086 | AH22: 120 | AI22: 216.27018 | AJ22: 944 | AK22: 430 | AL22: =(AK22*AJ22*AI22)/10^6 -> 87.788392 | AM22: =AL22*U22 -> 70.230713 | AN22: 92996.177 | AO22: =AH22*AI22 -> 25952.422 | AP22: =U22+AB22 -> 1 | AQ22: =AL22*AP22/(AG22+AE22) -> 3.0803932
A23: MAP037 | B23: RESIDENCIAL JARDIM EUROPA - BARRA DOS COQUEIROS | C23: https://earth.google.com/web/search/BARRA+DOS+COQUEIROS/@-10.86709266,-36.98473154,9.11625276a,6838.59037115d,35y,0h,0t,0r/data=CiwiJgokCez0LUwI4RzAEc6AbPlB_xzAGXUWKXAsqkPAIYL6q2XpsUPAQgIIAToDCgEwQgIIAEoICJfn8a8FEAA?authuser=0 | D23: 1 | E23: LandBank | G23: 2046 | J23: 203 | K23: NORDESTE I | L23: BARRA DOS COQUEIROS | M23: SE | N23: RESIDENCIAL JARDIM EUROPA | O23: Compra e Venda | P23: 4000000 | Q23: Loteamento | R23: - | S23: 2028 | T23: 46934 | U23: 0.8 | W23: =SUM(U23:V23) -> 0.8 | AA23: 0.198 | AB23: 0.2 | AC23: =AI23*AJ23 -> 204159.05 | AE23: =P23/10^6 -> 4 | AF23: =IF(AL23=0,0,AE23/AL23) -> 0.045564111 | AG23: =(AH23*AI23*AJ23)/10^6 -> 24.499086 | AH23: 120 | AI23: 216.49952 | AJ23: 943 | AK23: 430 | AL23: =(AK23*AJ23*AI23)/10^6 -> 87.788391 | AM23: =AL23*U23 -> 70.230713 | AN23: 93094.795 | AO23: =AH23*AI23 -> 25979.943 | AP23: =U23+AB23 -> 1 | AQ23: =AL23*AP23/(AG23+AE23) -> 3.0803932
A24: MAP038 | B24: JARDIM TROPICAL - CRATO | C24: https://earth.google.com/web/search/CRATO/@-7.23451766,-39.35968774,395.14410239a,4808.57124561d,35y,0h,0t,0r/data=CiwiJgokCREenKRkwgvAEaRMcJe6-AvAGbMRrrPsyUPAIf7hsFbW0EPAQgIIAToDCgEwQgIIAEoICJfn8a8FEAA?authuser=0 | D24: 1 | E24: LandBank | G24: 2053 | J24: 204 | K24: NORDESTE II | L24: CRATO | M24: CE | N24: JARDIM TROPICAL | O24: Compra e Venda | P24: 750000 | Q24: Loteamento | R24: Sim | S24: 2026 | T24: 46295 | U24: 0.725 | V24: 0.275 | W24: =SUM(U24:V24) -> 1 | X24: 0.05 | Y24: 0 | Z24: 0.068 | AA24: 0.198 | AC24: 187916 | AE24: =P24/10^6 -> 0.75 | AF24: =IF(AL24=0,0,AE24/AL24) -> 0.0066461787 | AG24: =(AH24*AI24*AJ24)/10^6 -> 22.56936 | AH24: 120 | AI24: 206 | AJ24: 913 | AK24: 600 | AL24: =(AK24*AJ24*AI24)/10^6 -> 112.8468 | AM24: =AL24*U24 -> 81.81393 | AN24: 108000 | AO24: =AH24*AI24 -> 24720 | AP24: =U24+AB24 -> 0.725 | AQ24: =AL24*AP24/(AG24+AE24) -> 3.5084123
A25: MAP039 | B25: JARDIM TROPICAL - ITAPIPOCA | C25: https://earth.google.com/web/search/ITAPIPOCA/@-3.48318447,-39.60453858,85.75014124a,4591.68380015d,35y,0h,0t,0r/data=CiwiJgokCSj18Ul83hfAEYrTwO0U8hfAGYnj-uRdJETAIcMsoPJeKUTAQgIIAToDCgEwQgIIAEoICJfn8a8FEAA?authuser=0 | D25: 1 | E25: LandBank | G25: 2054 | J25: 205 | K25: NORDESTE II | L25: ITAPIPOCA | M25: CE | N25: JARDIM TROPICAL | O25: Compra e Venda | P25: 750000 | Q25: Loteamento | R25: Sim | S25: 2026 | T25: 46295 | U25: 0.8 | V25: 0.2 | W25: =SUM(U25:V25) -> 1 | X25: 0.05 | Y25: 0 | Z25: 0.068 | AA25: 0.198 | AC25: 186731 | AE25: =P25/10^6 -> 0.75 | AF25: =IF(AL25=0,0,AE25/AL25) -> 0.0080479011 | AG25: =(AH25*AI25*AJ25)/10^6 -> 24.789072 | AH25: 133 | AI25: 176 | AJ25: 1059 | AK25: 500 | AL25: =(AK25*AJ25*AI25)/10^6 -> 93.192 | AM25: =AL25*U25 -> 74.5536 | AN25: 45000 | AO25: =AH25*AI25 -> 23408 | AP25: =U25+AB25 -> 0.8 | AQ25: =AL25*AP25/(AG25+AE25) -> 2.9191977
A26: MAP039 | B26: JARDIM TROPICAL II - ITAPIPOCA | C26: https://earth.google.com/web/search/ITAPIPOCA/@-3.48318447,-39.60453858,85.75014124a,4591.68380015d,35y,0h,0t,0r/data=CiwiJgokCSj18Ul83hfAEYrTwO0U8hfAGYnj-uRdJETAIcMsoPJeKUTAQgIIAToDCgEwQgIIAEoICJfn8a8FEAA?authuser=0 | D26: 1 | E26: LandBank | G26: 2054 | J26: 206 | K26: NORDESTE II | L26: ITAPIPOCA | M26: CE | N26: JARDIM TROPICAL II | O26: Compra e Venda | P26: 750000 | Q26: Loteamento | R26: Sim | S26: 2028 | T26: 47026 | U26: 0.8 | V26: 0.2 | W26: =SUM(U26:V26) -> 1 | X26: 0.05 | Y26: 0 | Z26: 0.068 | AA26: 0.198 | AC26: 186731 | AE26: =P26/10^6 -> 0.75 | AF26: =IF(AL26=0,0,AE26/AL26) -> 0.0080479011 | AG26: =(AH26*AI26*AJ26)/10^6 -> 24.789072 | AH26: 133 | AI26: 176 | AJ26: 1059 | AK26: 500 | AL26: =(AK26*AJ26*AI26)/10^6 -> 93.192 | AM26: =AL26*U26 -> 74.5536 | AN26: 45000 | AO26: =AH26*AI26 -> 23408 | AP26: =U26+AB26 -> 0.8 | AQ26: =AL26*AP26/(AG26+AE26) -> 2.9191977
A27: MAP040 | B27: JARDIM AMERICA II - TAUÁ | C27: https://earth.google.com/web/search/TAU%c3%81/@-5.97683983,-40.30366275,407.4430109a,2966.57752085d,35y,0h,0t,0r/data=CiwiJgokCVwuodN7uSdAEajZ7_kEaz3AGcctYEv-xi1AIcrxv7LiwVjAQgIIAToDCgEwQgIIAEoICJfn8a8FEAA?authuser=0 | D27: 1 | E27: LandBank | G27: 2056 | J27: 207 | K27: NORDESTE II | L27: TAUÁ | M27: CE | N27: JARDIM AMERICA II | O27: Parceria | P27: 0 | Q27: Loteamento | R27: Sim | S27: 2028 | T27: 46842 | U27: 0.79 | V27: 0.21 | W27: =SUM(U27:V27) -> 1 | X27: 0.05 | Y27: 0 | Z27: 0.068 | AA27: 0.198 | AC27: 201305 | AE27: =P27/10^6 -> 0 | AF27: =IF(AL27=0,0,AE27/AL27) -> 0 | AG27: =(AH27*AI27*AJ27)/10^6 -> 21.793536 | AH27: 108 | AI27: 192 | AJ27: 1051 | AK27: 480 | AL27: =(AK27*AJ27*AI27)/10^6 -> 96.86016 | AM27: =AL27*U27 -> 76.519526 | AN27: 43200 | AO27: =AH27*AI27 -> 20736 | AP27: =U27+AB27 -> 0.79 | AQ27: =AL27*AP27/(AG27+AE27) -> 3.5111111
A28: MAP040 | B28: JARDIM AMERICA III - TAUÁ | C28: https://earth.google.com/web/search/TAU%c3%81/@-5.97683983,-40.30366275,407.4430109a,2966.57752085d,35y,0h,0t,0r/data=CiwiJgokCVwuodN7uSdAEajZ7_kEaz3AGcctYEv-xi1AIcrxv7LiwVjAQgIIAToDCgEwQgIIAEoICJfn8a8FEAA?authuser=0 | D28: 1 | E28: LandBank | G28: 2056 | J28: 208 | K28: NORDESTE II | L28: TAUÁ | M28: CE | N28: JARDIM AMERICA III | O28: Parceria | P28: 0 | Q28: Loteamento | R28: Sim | S28: 2030 | T28: 47572 | U28: 0.79 | V28: 0.21 | W28: =SUM(U28:V28) -> 1 | X28: 0.05 | Y28: 0 | Z28: 0.068 | AA28: 0.198 | AC28: 201305 | AE28: =P28/10^6 -> 0 | AF28: =IF(AL28=0,0,AE28/AL28) -> 0 | AG28: =(AH28*AI28*AJ28)/10^6 -> 21.793536 | AH28: 108 | AI28: 192 | AJ28: 1051 | AK28: 480 | AL28: =(AK28*AJ28*AI28)/10^6 -> 96.86016 | AM28: =AL28*U28 -> 76.519526 | AN28: 43200 | AO28: =AH28*AI28 -> 20736 | AP28: =U28+AB28 -> 0.79 | AQ28: =AL28*AP28/(AG28+AE28) -> 3.5111111
A29: MAP041 | B29: RESIDENCIAL CIDADE JARDIM - BALSAS | C29: https://earth.google.com/web/search/BALSAS/@-7.55676262,-46.08364445,276.35723714a,5135.12989945d,35y,0h,0t,0r/data=CiwiJgokCeJxBz6CxDDAEQlwGFeXzDDAGfey9riu6UXAIWSXkF1C8kXAQgIIAToDCgEwQgIIAEoICJfn8a8FEAA?authuser=0 | D29: 1 | E29: LandBank | F29: REVER PROJETOS | G29: 2052 | J29: 209 | K29: NORDESTE II | L29: BALSAS | M29: MA | N29: RESIDENCIAL CIDADE JARDIM I - STP1 | O29: Parceria | P29: 0 | Q29: Loteamento | R29: Sim | S29: 2026 | T29: 46387 | U29: 0.8 | V29: 0.2 | W29: =SUM(U29:V29) -> 1 | X29: 0.05 | Y29: 0 | Z29: 0.068 | AA29: 0.198 | AC29: =AI29*AJ29 -> 306340 | AE29: =P29/10^6 -> 0 | AF29: =IF(AL29=0,0,AE29/AL29) -> 0 | AG29: =(AH29*AI29*AJ29)/10^6 -> 36.7608 | AH29: 120 | AI29: 265 | AJ29: 1156 | AK29: 500 | AL29: =(AK29*AJ29*AI29)/10^6 -> 153.17 | AM29: =AL29*U29 -> 122.536 | AN29: 132616.47 | AO29: =AH29*AI29 -> 31800 | AP29: =U29+AB29 -> 0.8 | AQ29: =AL29*AP29/(AG29+AE29) -> 3.3333333
A30: MAP041 | B30: RESIDENCIAL CIDADE JARDIM - SUBETAPA2 - BALSAS | C30: https://earth.google.com/web/search/BALSAS/@-7.55676262,-46.08364445,276.35723714a,5135.12989945d,35y,0h,0t,0r/data=CiwiJgokCeJxBz6CxDDAEQlwGFeXzDDAGfey9riu6UXAIWSXkF1C8kXAQgIIAToDCgEwQgIIAEoICJfn8a8FEAA?authuser=0 | D30: 1 | E30: LandBank | F30: REVER PROJETOS | G30: 2052 | J30: 210 | K30: NORDESTE II | L30: BALSAS | M30: MA | N30: RESIDENCIAL CIDADE JARDIM I - STP2 | O30: Parceria | P30: 0 | Q30: Loteamento | R30: Sim | S30: 2027 | T30: 46660 | U30: 0.8 | V30: 0.2 | W30: =SUM(U30:V30) -> 1 | X30: 0.05 | Y30: 0 | Z30: 0.068 | AA30: 0.198 | AC30: =AI30*AJ30 -> 306340 | AE30: =P30/10^6 -> 0 | AF30: =IF(AL30=0,0,AE30/AL30) -> 0 | AG30: =(AH30*AI30*AJ30)/10^6 -> 36.7608 | AH30: 120 | AI30: 265 | AJ30: 1156 | AK30: 500 | AL30: =(AK30*AJ30*AI30)/10^6 -> 153.17 | AM30: =AL30*U30 -> 122.536 | AN30: 132616.47 | AO30: =AH30*AI30 -> 31800 | AP30: =U30+AB30 -> 0.8 | AQ30: =AL30*AP30/(AG30+AE30) -> 3.3333333
A31: MAP042 | B31: RESIDENCIAL CIDADE JARDIM II - BALSAS | C31: https://earth.google.com/web/search/BALSAS/@-7.55676262,-46.08364445,276.35723714a,5135.12989945d,35y,0h,0t,0r/data=CiwiJgokCeJxBz6CxDDAEQlwGFeXzDDAGfey9riu6UXAIWSXkF1C8kXAQgIIAToDCgEwQgIIAEoICJfn8a8FEAA?authuser=0 | D31: 1 | E31: LandBank | F31: REVER PROJETOS | G31: 2052 | J31: 211 | K31: NORDESTE II | L31: BALSAS | M31: MA | N31: RESIDENCIAL CIDADE JARDIM II | O31: Parceria | P31: 0 | Q31: Loteamento | R31: - | S31: 2029 | T31: 47391 | U31: 0.8 | V31: 0.2 | W31: =SUM(U31:V31) -> 1 | X31: 0.05 | Y31: 0 | Z31: 0.068 | AA31: 0.198 | AC31: =AI31*AJ31 -> 271890 | AE31: =P31/10^6 -> 0 | AF31: =IF(AL31=0,0,AE31/AL31) -> 0 | AG31: =(AH31*AI31*AJ31)/10^6 -> 32.6268 | AH31: 120 | AI31: 265 | AJ31: 1026 | AK31: 500 | AL31: =(AK31*AJ31*AI31)/10^6 -> 135.945 | AM31: =AL31*U31 -> 108.756 | AN31: 124993.83 | AO31: =AH31*AI31 -> 31800 | AP31: =U31+AB31 -> 0.8 | AQ31: =AL31*AP31/(AG31+AE31) -> 3.3333333
A32: MAP042 | B32: RESIDENCIAL CIDADE JARDIM III - BALSAS | C32: https://earth.google.com/web/search/BALSAS/@-7.55676262,-46.08364445,276.35723714a,5135.12989945d,35y,0h,0t,0r/data=CiwiJgokCeJxBz6CxDDAEQlwGFeXzDDAGfey9riu6UXAIWSXkF1C8kXAQgIIAToDCgEwQgIIAEoICJfn8a8FEAA?authuser=0 | D32: 1 | E32: LandBank | F32: REVER PROJETOS | G32: 2052 | J32: 212 | K32: NORDESTE II | L32: BALSAS | M32: MA | N32: RESIDENCIAL CIDADE JARDIM III | O32: Parceria | P32: 0 | Q32: Loteamento | R32: - | S32: 2030 | T32: 48487 | U32: 0.8 | V32: 0.2 | W32: =SUM(U32:V32) -> 1 | X32: 0.05 | Y32: 0 | Z32: 0.068 | AA32: 0.198 | AC32: =AI32*AJ32 -> 271890 | AE32: =P32/10^6 -> 0 | AF32: =IF(AL32=0,0,AE32/AL32) -> 0 | AG32: =(AH32*AI32*AJ32)/10^6 -> 32.6268 | AH32: 120 | AI32: 265 | AJ32: 1026 | AK32: 500 | AL32: =(AK32*AJ32*AI32)/10^6 -> 135.945 | AM32: =AL32*U32 -> 108.756 | AN32: 124993.83 | AO32: =AH32*AI32 -> 31800 | AP32: =U32+AB32 -> 0.8 | AQ32: =AL32*AP32/(AG32+AE32) -> 3.3333333
A33: MAP002 | B33: A DEFINIR - ELDORADO DO CARAJAS | C33: https://earth.google.com/web/search/A+DEFINIR+-+ELDORADO+DO+CARAJAS/@-6.10130618,-49.38645125,132.08489807a,3593.41495385d,35y,0h,0t,0r/data=CiwiJgokCW1sITprhAPAEVxoH91ezwPAGZD9qRETXkvAIZjXKt-ZZ0vAQgIIAToDCgEwQgIIAEoICJfn8a8FEAA?authuser=0 | D33: Ativo | E33: LandBank | G33: 2119 | J33: 136 | K33: NORTE | L33: ELDORADO DO CARAJAS | M33: PA | N33: A DEFINIR | O33: Compra e Venda | P33: 84310 | Q33: Loteamento | R33: - | S33: - | T33: - | U33: 1 | W33: =SUM(U33:V33) -> 1 | AA33: 0.198 | AC33: =AI33*AJ33 -> 136646.78 | AE33: =P33/10^6 -> 0.08431 | AF33: =IF(AL33=0,0,AE33/AL33) -> 0.0022811147 | AG33: =(AH33*AI33*AJ33)/10^6 -> 10.931742 | AH33: 80 | AI33: 221.82919 | AJ33: 616 | AK33: 270.47838 | AL33: =(AK33*AJ33*AI33)/10^6 -> 36.96 | AM33: =AL33*U33 -> 36.96 | AN33: 60000 | AO33: =AH33*AI33 -> 17746.335 | AP33: =U33+AB33 -> 1 | AQ33: =AL33*AP33/(AG33+AE33) -> 3.3551039
A34: MAP003 | B34: CIDADE JARDIM III - PARAGOMINAS | C34: https://earth.google.com/web/search/CIDADE+JARDIM+III+-+PARAGOMINAS/@-2.98095416,-47.3799762,134.97977097a,3030.5675351d,34.99995839y,0h,0t,0r/data=CiwiJgokCSuOdv50fyPAET9A346_gyPAGQZ87NXc6kHAIQ521gYT7UHAQgIIAToDCgEwQgIIAEoICJfn8a8FEAA?authuser=0 | D34: 1 | E34: LandBank | G34: 2115 | H34: 4 | J34: 137 | K34: NORTE | L34: PARAGOMINAS | M34: PA | N34: CIDADE JARDIM III | O34: Compra e Venda | P34: 60000 | Q34: Loteamento | R34: Sim | S34: - | T34: - | U34: 1 | W34: =SUM(U34:V34) -> 1 | AA34: 0.198 | AC34: =AI34*AJ34 -> 11175.27 | AE34: =P34/10^6 -> 0.06 | AF34: =IF(AL34=0,0,AE34/AL34) -> 0.013953488 | AG34: =(AH34*AI34*AJ34)/10^6 -> 0.8940216 | AH34: 80 | AI34: 259.89 | AJ34: 43 | AK34: 384.77818 | AL34: =(AK34*AJ34*AI34)/10^6 -> 4.3 | AM34: =AL34*U34 -> 4.3 | AN34: 100000 | AO34: =AH34*AI34 -> 20791.2 | AP34: =U34+AB34 -> 1 | AQ34: =AL34*AP34/(AG34+AE34) -> 4.5072355
A35: MAP003 | B35: CIDADE JARDIM IV - PARAGOMINAS | C35: https://earth.google.com/web/search/CIDADE+JARDIM+III+-+PARAGOMINAS/@-2.98095416,-47.3799762,134.97977097a,3030.5675351d,34.99995839y,0h,0t,0r/data=CiwiJgokCSuOdv50fyPAET9A346_gyPAGQZ87NXc6kHAIQ521gYT7UHAQgIIAToDCgEwQgIIAEoICJfn8a8FEAA?authuser=0 | D35: 1 | E35: LandBank | G35: 2115 | H35: 4 | J35: 138 | K35: NORTE | L35: PARAGOMINAS | M35: PA | N35: CIDADE JARDIM IV | O35: Compra e Venda | P35: 60000 | Q35: Loteamento | R35: Sim | S35: - | T35: - | U35: 1 | W35: =SUM(U35:V35) -> 1 | AA35: 0.198 | AC35: =AI35*AJ35 -> 21556.5 | AE35: =P35/10^6 -> 0.06 | AF35: =IF(AL35=0,0,AE35/AL35) -> 0.0064935065 | AG35: =(AH35*AI35*AJ35)/10^6 -> 1.72452 | AH35: 80 | AI35: 279.95455 | AJ35: 77 | AK35: 428.64101 | AL35: =(AK35*AJ35*AI35)/10^6 -> 9.24 | AM35: =AL35*U35 -> 9.24 | AN35: 120000 | AO35: =AH35*AI35 -> 22396.364 | AP35: =U35+AB35 -> 1 | AQ35: =AL35*AP35/(AG35+AE35) -> 5.177863
A36: MAP006 | B36: DEFINIR - ÁREA SERRARIA CUMARU - REDENÇÃO | C36: https://earth.google.com/web/search/Reden%c3%a7%c3%a3o,+PA/@-8.02281704,-50.02474338,207.09019485a,9467.67478846d,35y,-0h,0t,0r/data=Cn0aTxJJCiUweDkyZTAwODAxOTFiMWU4Mzk6MHgzZDhmOGEwNDFiM2MxMGRkGS5nALkODyDAIUkmTL0TBEnAKg5SZWRlbsOnw6NvLCBQQRgCIAEiJgokCVbvBcmbxgfAEZZRXQph6wfAGYZHDZRMrkfAIcoEsIr5skfAQgIIAToDCgEwQgIIAEoICJfn8a8FEAA?authuser=0 | D36: 1 | E36: LandBank | G36: 2117 | J36: 145 | K36: NORTE | L36: REDENÇÃO | M36: PA | N36: A DEFINIR - ÁREA SERRARIA CUMARU | O36: Compra e Venda | P36: 2372312.5 | Q36: Loteamento | R36: - | S36: - | T36: - | U36: 1 | W36: =SUM(U36:V36) -> 1 | AA36: 0.198 | AC36: =AI36*AJ36 -> 43078.78 | AE36: =P36/10^6 -> 2.3723125 | AF36: =IF(AL36=0,0,AE36/AL36) -> 0.16474392 | AG36: =(AH36*AI36*AJ36)/10^6 -> 3.4463024 | AH36: 80 | AI36: 2393.2656 | AJ36: 18 | AK36: 334.2713 | AL36: =(AK36*AJ36*AI36)/10^6 -> 14.4 | AM36: =AL36*U36 -> 14.4 | AN36: 800000 | AO36: =AH36*AI36 -> 191461.24 | AP36: =U36+AB36 -> 1 | AQ36: =AL36*AP36/(AG36+AE36) -> 2.4748158
A37: MAP007 | B37: RESIDENCIAL BELA VISTA - REDENÇÃO | C37: https://earth.google.com/web/search/Reden%c3%a7%c3%a3o,+PA/@-8.02281704,-50.02474338,207.09019485a,9467.67478846d,35y,-0h,0t,0r/data=Cn0aTxJJCiUweDkyZTAwODAxOTFiMWU4Mzk6MHgzZDhmOGEwNDFiM2MxMGRkGS5nALkODyDAIUkmTL0TBEnAKg5SZWRlbsOnw6NvLCBQQRgCIAEiJgokCVbvBcmbxgfAEZZRXQph6wfAGYZHDZRMrkfAIcoEsIr5skfAQgIIAToDCgEwQgIIAEoICJfn8a8FEAA?authuser=0 | D37: 1 | E37: LandBank | G37: 2116 | J37: 146 | K37: NORTE | L37: REDENÇÃO | M37: PA | N37: RESIDENCIAL BELA VISTA | O37: Compra e Venda | P37: 2372312.5 | Q37: Loteamento | R37: - | S37: 2026 | T37: 46387 | U37: 0.99 | W37: =SUM(U37:V37) -> 0.99 | AA37: 0.198 | AB37: 0.01 | AC37: =AI37*AJ37 -> 130680 | AE37: =P37/10^6 -> 2.3723125 | AF37: =IF(AL37=0,0,AE37/AL37) -> 0.042217675 | AG37: =(AH37*AI37*AJ37)/10^6 -> 17.393508 | AH37: 133.1 | AI37: 220 | AJ37: 594 | AK37: 430 | AL37: =(AK37*AJ37*AI37)/10^6 -> 56.1924 | AM37: =AL37*U37 -> 55.630476 | AN37: 94600 | AO37: =AH37*AI37 -> 29282 | AP37: =U37+AB37 -> 1 | AQ37: =AL37*AP37/(AG37+AE37) -> 2.8429075
A38: MAP008 | B38: CIDADE JARDIM III - SUBETAPA 1 - SANTARÉM | C38: https://earth.google.com/web/search/CIDADE+JARDIM+12+-+PARAUAPEBAS/@-2.45795692,-54.77217012,46.50042218a,6405.178905d,35y,-0h,0t,0r/data=CiwiJgokCdmVqMeMyQbAESVW3mJaMwnAGYI6tUF7jUfAIaCAQToN3EfAQgIIAToDCgEwQgIIAEoICJfn8a8FEAA | D38: 1 | E38: LandBank | G38: 2121 | J38: 147 | K38: NORTE | L38: SANTARÉM | M38: PA | N38: CIDADE JARDIM III - SUBETAPA 1 | O38: Aquisição de Cotas | P38: 4800000 | Q38: Loteamento | R38: Sim | S38: 2026 | T38: 46387 | U38: 1 | W38: =SUM(U38:V38) -> 1 | AA38: 0.198 | AC38: =AI38*AJ38 -> 268937.01 | AE38: =P38/10^6 -> 4.8 | AF38: =IF(AL38=0,0,AE38/AL38) -> 0.027458532 | AG38: =(AH38*AI38*AJ38)/10^6 -> 35.795516 | AH38: 133.1 | AI38: 279.27 | AJ38: 963 | AK38: 650 | AL38: =(AK38*AJ38*AI38)/10^6 -> 174.80906 | AM38: =AL38*U38 -> 174.80906 | AN38: 168559.39 | AO38: =AH38*AI38 -> 37170.837 | AP38: =U38+AB38 -> 1 | AQ38: =AL38*AP38/(AG38+AE38) -> 4.3061174
A39: MAP008 | B39: CIDADE JARDIM III - SUBETAPA 2 - SANTARÉM | C39: https://earth.google.com/web/search/CIDADE+JARDIM+12+-+PARAUAPEBAS/@-2.45795692,-54.77217012,46.50042218a,6405.178905d,35y,-0h,0t,0r/data=CiwiJgokCdmVqMeMyQbAESVW3mJaMwnAGYI6tUF7jUfAIaCAQToN3EfAQgIIAToDCgEwQgIIAEoICJfn8a8FEAA | D39: 1 | E39: LandBank | G39: 2121 | J39: 148 | K39: NORTE | L39: SANTARÉM | M39: PA | N39: CIDADE JARDIM III - SUBETAPA 2 | O39: Aquisição de Cotas | P39: 4800000 | Q39: Loteamento | R39: Sim | S39: 2027 | T39: 46752 | U39: 1 | W39: =SUM(U39:V39) -> 1 | AA39: 0.198 | AC39: =AI39*AJ39 -> 269216.28 | AE39: =P39/10^6 -> 4.8 | AF39: =IF(AL39=0,0,AE39/AL39) -> 0.027430048 | AG39: =(AH39*AI39*AJ39)/10^6 -> 35.832687 | AH39: 133.1 | AI39: 279.27 | AJ39: 964 | AK39: 650 | AL39: =(AK39*AJ39*AI39)/10^6 -> 174.99058 | AM39: =AL39*U39 -> 174.99058 | AN39: 168559.39 | AO39: =AH39*AI39 -> 37170.837 | AP39: =U39+AB39 -> 1 | AQ39: =AL39*AP39/(AG39+AE39) -> 4.3066456
A40: MAP009 | B40: CIDADE JARDIM IV - SANTARÉM | C40: https://earth.google.com/web/search/CIDADE+JARDIM+12+-+PARAUAPEBAS/@-2.45795692,-54.77217012,46.50042218a,6405.178905d,35y,-0h,0t,0r/data=CiwiJgokCdmVqMeMyQbAESVW3mJaMwnAGYI6tUF7jUfAIaCAQToN3EfAQgIIAToDCgEwQgIIAEoICJfn8a8FEAA | D40: 1 | E40: LandBank | G40: 2121 | J40: 149 | K40: NORTE | L40: SANTARÉM | M40: PA | N40: CIDADE JARDIM IV | O40: Aquisição de Cotas | P40: 4800000 | Q40: Loteamento | R40: Sim | S40: 2028 | T40: 47118 | U40: 1 | W40: =SUM(U40:V40) -> 1 | AA40: 0.198 | AC40: =AI40*AJ40 -> 410455.51 | AE40: =P40/10^6 -> 4.8 | AF40: =IF(AL40=0,0,AE40/AL40) -> 0.023388649 | AG40: =(AH40*AI40*AJ40)/10^6 -> 54.631628 | AH40: 133.1 | AI40: 239.89217 | AJ40: 1711 | AK40: 500 | AL40: =(AK40*AJ40*AI40)/10^6 -> 205.22776 | AM40: =AL40*U40 -> 205.22776 | AN40: 119946.09 | AO40: =AH40*AI40 -> 31929.648 | AP40: =U40+AB40 -> 1 | AQ40: =AL40*AP40/(AG40+AE40) -> 3.453174
...

Sheet Planilha2
G1: =COUNTA(_xlfn.ANCHORARRAY(G4)) -> 76 | H1: =COUNTA(_xlfn.ANCHORARRAY(H4)) -> 19
B2: Resumo Executivo | G2: =G1-1 -> 75 | H2: =H1-1 -> 18
G3: cidade | H3: uf
B4: Empreendimentos | G4: {=_xlfn.UNIQUE(AREAS!L2:L1048576)} -> BELA VISTA DE GOIÁS | H4: {=_xlfn.UNIQUE(AREAS!M2:M1048576)} -> GO | L4: =COUNTA(L6:L77) -> 72
B5: =COUNTA(AREAS!N2:N243) -> 242 | G5: GOIÂNIA | H5: RO | L5: Cidade | M5: Qtde | N5: Ativo | P5: ELDORADO DO CARAJAS | Q5: =COUNTIF(AREAS!L:L,Planilha2!P5) -> 1 | R5: =_xlfn.XLOOKUP(P5,AREAS!L:L,AREAS!D:D,"não") -> Ativo
G6: PORTO VELHO | H6: AL | K6: RIO BRANCO | L6: PARAGOMINAS | M6: =COUNTIF(AREAS!L:L,Planilha2!L6) -> 2 | N6: =_xlfn.XLOOKUP(L6,AREAS!L:L,AREAS!D:D,"não") -> 1 | P6: PARAUAPEBAS | Q6: 5 | R6: 0
B7: Cidades | C7: Estados (UF) | G7: CALDAS NOVAS | H7: PB | K7: ARAPIRACA | L7: FERNANDOPOLIS | M7: =COUNTIF(AREAS!L:L,Planilha2!L7) -> 1 | N7: =_xlfn.XLOOKUP(L7,AREAS!L:L,AREAS!D:D,"não") -> 1 | P7: POÇOS DE CALDAS | Q7: =COUNTIF(AREAS!L:L,Planilha2!P7) -> 2 | R7: =_xlfn.XLOOKUP(P7,AREAS!L:L,AREAS!D:D,"não") -> 0
B8: =G2 -> 75 | C8: =H2 -> 18 | G8: ARAPIRACA | H8: SE | K8: MARECHAL DEODORO | L8: ITAPETININGA | M8: =COUNTIF(AREAS!L:L,Planilha2!L8) -> 2 | N8: =_xlfn.XLOOKUP(L8,AREAS!L:L,AREAS!D:D,"não") -> 1
G9: MARECHAL DEODORO | H9: CE | K9: PENEDO | L9: ITAPETININGA | M9: =COUNTIF(AREAS!L:L,Planilha2!L9) -> 7 | N9: =_xlfn.XLOOKUP(L9,AREAS!L:L,AREAS!D:D,"não") -> 1
B10: Total de Unidades | G10: RIO LARGO | H10: MA | K10: RIO LARGO | L10: REDENÇÃO | M10: =COUNTIF(AREAS!L:L,Planilha2!L10) -> 2 | N10: =_xlfn.XLOOKUP(L10,AREAS!L:L,AREAS!D:D,"não") -> 1
B11: =SUM(AREAS!AJ2:AJ243) -> 207735.02 | G11: PENEDO | H11: PA | K11: SÃO MIGUEL DOS CAMPOS | L11: SANTARÉM | M11: =COUNTIF(AREAS!L:L,Planilha2!L11) -> 5 | N11: =_xlfn.XLOOKUP(L11,AREAS!L:L,AREAS!D:D,"não") -> 1
G12: ALAGOINHA | H12: MT | K12: ALAGOINHAS | L12: XINGUARA | M12: =COUNTIF(AREAS!L:L,Planilha2!L12) -> 1 | N12: =_xlfn.XLOOKUP(L12,AREAS!L:L,AREAS!D:D,"não") -> 1
B13: Área Total | G13: BARRA DOS COQUEIROS | H13: AC | K13: BARREIRAS | L13: SANTANA DO ARAGUAIA | M13: =COUNTIF(AREAS!L:L,Planilha2!L13) -> 7 | N13: =_xlfn.XLOOKUP(L13,AREAS!L:L,AREAS!D:D,"não") -> 1
B14: =SUM(AREAS!AC2:AC243) -> 52559402 | C14: =B14/10000 -> 5255.9402 | G14: CRATO | H14: ES | K14: CRATO | L14: OURILÂNDIA DO NORTE | M14: =COUNTIF(AREAS!L:L,Planilha2!L14) -> 1 | N14: =_xlfn.XLOOKUP(L14,AREAS!L:L,AREAS!D:D,"não") -> 1
G15: ITAPIPOCA | H15: SP | K15: ITAPIPOCA | L15: PALMAS | M15: =COUNTIF(AREAS!L:L,Planilha2!L15) -> 25 | N15: =_xlfn.XLOOKUP(L15,AREAS!L:L,AREAS!D:D,"não") -> 1
B16: VGV Total | G16: TAUÁ | H16: MG | K16: TAUÁ | L16: BARREIRAS | M16: =COUNTIF(AREAS!L:L,Planilha2!L16) -> 2 | N16: =_xlfn.XLOOKUP(L16,AREAS!L:L,AREAS!D:D,"não") -> 1
B17: =SUM(AREAS!AL2:AL243) -> 33376.909 | G17: BALSAS | H17: RJ | K17: COLATINA | L17: FORMOSA | M17: =COUNTIF(AREAS!L:L,Planilha2!L17) -> 2 | N17: =_xlfn.XLOOKUP(L17,AREAS!L:L,AREAS!D:D,"não") -> 1
B18: VGV Total BT | G18: ELDORADO DO CARAJAS | H18: RS | K18: BELA VISTA DE GOIÁS | L18: ARAPIRACA | M18: =COUNTIF(AREAS!L:L,Planilha2!L18) -> 2 | N18: =_xlfn.XLOOKUP(L18,AREAS!L:L,AREAS!D:D,"não") -> 1
B19: =SUM(AREAS!AM2:AM243) -> 20967.496 | G19: PARAGOMINAS | H19: TO | K19: CALDAS NOVAS | L19: MARECHAL DEODORO | M19: =COUNTIF(AREAS!L:L,Planilha2!L19) -> 1 | N19: =_xlfn.XLOOKUP(L19,AREAS!L:L,AREAS!D:D,"não") -> 1
G20: REDENÇÃO | H20: PR | K20: FORMOSA | L20: RIO LARGO | M20: =COUNTIF(AREAS!L:L,Planilha2!L20) -> 3 | N20: =_xlfn.XLOOKUP(L20,AREAS!L:L,AREAS!D:D,"não") -> 1
G21: SANTARÉM | H21: BA | K21: GOIÂNIA | L21: PENEDO | M21: =COUNTIF(AREAS!L:L,Planilha2!L21) -> 1 | N21: =_xlfn.XLOOKUP(L21,AREAS!L:L,AREAS!D:D,"não") -> 1
G22: XINGUARA | H22: 0 | K22: NOVO GAMA | L22: ALAGOINHA | M22: =COUNTIF(AREAS!L:L,Planilha2!L22) -> 1 | N22: =_xlfn.XLOOKUP(L22,AREAS!L:L,AREAS!D:D,"não") -> 1
G23: SANTANA DO ARAGUAIA | K23: PORANGATU | L23: BARRA DOS COQUEIROS | M23: =COUNTIF(AREAS!L:L,Planilha2!L23) -> 2 | N23: =_xlfn.XLOOKUP(L23,AREAS!L:L,AREAS!D:D,"não") -> 1
G24: OURILÂNDIA DO NORTE | K24: RIO VERDE | L24: CRATO | M24: =COUNTIF(AREAS!L:L,Planilha2!L24) -> 1 | N24: =_xlfn.XLOOKUP(L24,AREAS!L:L,AREAS!D:D,"não") -> 1
G25: PARAUAPEBAS | K25: ÁGUAS LINDAS DE GOIÁS | L25: ITAPIPOCA | M25: =COUNTIF(AREAS!L:L,Planilha2!L25) -> 2 | N25: =_xlfn.XLOOKUP(L25,AREAS!L:L,AREAS!D:D,"não") -> 1
G26: CONCEIÇÃO DO ARAGUAIA | K26: BALSAS | L26: TAUÁ | M26: =COUNTIF(AREAS!L:L,Planilha2!L26) -> 2 | N26: =_xlfn.XLOOKUP(L26,AREAS!L:L,AREAS!D:D,"não") -> 1
G27: VARZEA GRANDE | K27: MONTES CLAROS | L27: BALSAS | M27: =COUNTIF(AREAS!L:L,Planilha2!L27) -> 4 | N27: =_xlfn.XLOOKUP(L27,AREAS!L:L,AREAS!D:D,"não") -> 1
G28: RIO BRANCO | K28: NOVA SERRANA | L28: MONTES CLAROS | M28: =COUNTIF(AREAS!L:L,Planilha2!L28) -> 3 | N28: =_xlfn.XLOOKUP(L28,AREAS!L:L,AREAS!D:D,"não") -> 1
G29: CÁCERES | K29: UBERABA | L29: ITATIAIA | M29: =COUNTIF(AREAS!L:L,Planilha2!L29) -> 5 | N29: =_xlfn.XLOOKUP(L29,AREAS!L:L,AREAS!D:D,"não") -> 1
G30: TANGARÁ DA SERRA | K30: ALTA FLORESTA | L30: COLATINA | M30: =COUNTIF(AREAS!L:L,Planilha2!L30) -> 4 | N30: =_xlfn.XLOOKUP(L30,AREAS!L:L,AREAS!D:D,"não") -> 1
G31: CUIABÁ | K31: CHAPADA DOS GUIMARÃES | L31: VARGEM GRANDE | M31: =COUNTIF(AREAS!L:L,Planilha2!L31) -> 1 | N31: =_xlfn.XLOOKUP(L31,AREAS!L:L,AREAS!D:D,"não") -> 1
G32: CACOAL | K32: CUIABÁ | L32: DUQUE DE CAXIAS | M32: =COUNTIF(AREAS!L:L,Planilha2!L32) -> 4 | N32: =_xlfn.XLOOKUP(L32,AREAS!L:L,AREAS!D:D,"não") -> 1
G33: JI-PARANÁ | K33: CÁCERES | L33: LUZIMANGUES | M33: =COUNTIF(AREAS!L:L,Planilha2!L33) -> 3 | N33: =_xlfn.XLOOKUP(L33,AREAS!L:L,AREAS!D:D,"não") -> 1
G34: ROLIM DE MOURA | K34: TANGARÁ DA SERRA | L34: ITABORAÍ | M34: =COUNTIF(AREAS!L:L,Planilha2!L34) -> 2 | N34: =_xlfn.XLOOKUP(L34,AREAS!L:L,AREAS!D:D,"não") -> 1
... G36: CHAPADA DOS GUIMARÃES | K36: CANAÃ DOS CARAJÁS | L36: ARRAIAL DO CABO | M36: =COUNTIF(AREAS!L:L,Planilha2!L36) -> 2 | N36: =_xlfn.XLOOKUP(L36,AREAS!L:L,AREAS!D:D,"não") -> 1
G37: GUARANTÃ DO NORTE | K37: CONCEIÇÃO DO ARAGUAIA | L37: PARAUAPEBAS | M37: 1 | N37: =_xlfn.XLOOKUP(L37,AREAS!L:L,AREAS!D:D,"não") -> 1
G38: COLATINA | K38: ELDORADO DOS CARAJÁS | L38: PORANGATU | M38: =COUNTIF(AREAS!L:L,Planilha2!L38) -> 1 | N38: =_xlfn.XLOOKUP(L38,AREAS!L:L,AREAS!D:D,"não") -> 1
G39: FERNANDOPOLIS | K39: ITAITUBA | L39: LORENA | M39: =COUNTIF(AREAS!L:L,Planilha2!L39) -> 6 | N39: =_xlfn.XLOOKUP(L39,AREAS!L:L,AREAS!D:D,"não") -> 1
G40: ITAPETININGA | K40: MARABÁ | L40: PRESIDENTE PRUDENTE | M40: =COUNTIF(AREAS!L:L,Planilha2!L40) -> 6 | N40: =_xlfn.XLOOKUP(L40,AREAS!L:L,AREAS!D:D,"não") -> 1
G41: ITAPETININGA | K41: OURILÂNDIA DO NORTE | L41: CAÇAPAVA | M41: =COUNTIF(AREAS!L:L,Planilha2!L41) -> 1 | N41: =_xlfn.XLOOKUP(L41,AREAS!L:L,AREAS!D:D,"não") -> 1
...
